<?xml version="1.0" ?>
<!-- =================================================================================== -->
<!-- |    This document was autogenerated by xacro from workcell.xacro                 | -->
<!-- |    EDITING THIS FILE BY HAND IS NOT RECOMMENDED                                 | -->
<!-- =================================================================================== -->
<robot name="fanuc_crx10ial">
  <!-- links: main serial chain -->
  <link name="base_link">
    <collision>
      <origin rpy="0 0 0" xyz="0 0 0"/>
      <geometry>
        <mesh filename="package://fanuc_crx10ia_support/meshes/crx10ial/collision/base_link.stl"/>
      </geometry>
    </collision>
  </link>
  <link name="link_1">
    <collision>
      <origin rpy="0 0 0" xyz="0 0 0"/>
      <geometry>
        <mesh filename="package://fanuc_crx10ia_support/meshes/crx10ial/collision/link_1.stl"/>
      </geometry>
    </collision>
  </link>
  <link name="link_2">
    <collision>
      <origin rpy="0 0 0" xyz="0 0 0"/>
      <geometry>
        <mesh filename="package://fanuc_crx10ia_support/meshes/crx10ial/collision/link_2.stl"/>
      </geometry>
    </collision>
  </link>
  <link name="link_3">
    <collision>
      <origin rpy="0 0 0" xyz="0 0 0"/>
      <geometry>
        <mesh filename="package://fanuc_crx10ia_support/meshes/crx10ial/collision/link_3.stl"/>
      </geometry>
    </collision>
  </link>
  <link name="link_4">
    <collision>
      <origin rpy="0 0 0" xyz="0 0 0"/>
      <geometry>
        <mesh filename="package://fanuc_crx10ia_support/meshes/crx10ial/collision/link_4.stl"/>
      </geometry>
    </collision>
  </link>
  <link name="link_5">
    <collision>
      <origin rpy="0 0 0" xyz="0 0 0"/>
      <geometry>
        <mesh filename="package://fanuc_crx10ia_support/meshes/crx10ial/collision/link_5.stl"/>
      </geometry>
    </collision>
  </link>
  <link name="link_6">
    <collision>
      <origin rpy="0 0 0" xyz="0 0 0"/>
      <geometry>
        <mesh filename="package://fanuc_crx10ia_support/meshes/crx10ial/collision/link_6.stl"/>
      </geometry>
    </collision>
  </link>
  <!-- joints: main serial chain -->
  <joint name="joint_1" type="revolute">
    <origin rpy="0 0 0" xyz="0 0 0.245"/>
    <parent link="base_link"/>
    <child link="link_1"/>
    <axis xyz="0 0 1"/>
    <limit effort="0" lower="-3.141592653589793" upper="3.141592653589793" velocity="2.0943951023931953"/>
  </joint>
  <joint name="joint_2" type="revolute">
    <origin rpy="0 0 0" xyz="0 0 0"/>
    <parent link="link_1"/>
    <child link="link_2"/>
    <axis xyz="0 1 0"/>
    <limit effort="0" lower="-3.141592653589793" upper="3.141592653589793" velocity="2.0943951023931953"/>
  </joint>
  <joint name="joint_3" type="revolute">
    <origin rpy="0 0 0" xyz="0 0 0.710"/>
    <parent link="link_2"/>
    <child link="link_3"/>
    <axis xyz="0 -1 0"/>
    <limit effort="0" lower="-4.71238898038469" upper="4.71238898038469" velocity="3.141592653589793"/>
  </joint>
  <joint name="joint_4" type="revolute">
    <origin rpy="0 0 0" xyz="0 0 0"/>
    <parent link="link_3"/>
    <child link="link_4"/>
    <axis xyz="-1 0 0"/>
    <limit effort="0" lower="-3.3161255787892263" upper="3.3161255787892263" velocity="3.141592653589793"/>
  </joint>
  <joint name="joint_5" type="revolute">
    <origin rpy="0 0 0" xyz="0.540 -0.150 0"/>
    <parent link="link_4"/>
    <child link="link_5"/>
    <axis xyz="0 -1 0"/>
    <limit effort="0" lower="-3.141592653589793" upper="3.141592653589793" velocity="3.141592653589793"/>
  </joint>
  <joint name="joint_6" type="revolute">
    <origin rpy="0 0 0" xyz="0.160 0 0"/>
    <parent link="link_5"/>
    <child link="link_6"/>
    <axis xyz="-1 0 0"/>
    <limit effort="0" lower="-3.3161255787892263" upper="3.3161255787892263" velocity="3.141592653589793"/>
  </joint>
  <!-- ROS-Industrial 'base' frame: base_link to Fanuc World Coordinates transform -->
  <link name="base"/>
  <joint name="base_link-base" type="fixed">
    <origin rpy="0 0 0" xyz="0 0 0.245"/>
    <parent link="base_link"/>
    <child link="base"/>
  </joint>
  <!-- ROS-Industrial 'flange' frame: attachment point for EEF models -->
  <link name="flange"/>
  <joint name="joint_6-flange" type="fixed">
    <origin rpy="0 0 0" xyz="0 0 0"/>
    <parent link="link_6"/>
    <child link="flange"/>
  </joint>
  <!-- ROS-Industrial 'tool0' frame: all-zeros tool frame -->
  <link name="tool0"/>
  <joint name="link_6-tool0" type="fixed">
    <origin rpy="3.141592653589793 -1.5707963267948966 0" xyz="0 0 0"/>
    <parent link="flange"/>
    <child link="tool0"/>
  </joint>
  <!--Define additionnal link to robot-->
  <link name="festool_kit">
    <collision>
      <origin rpy="3.1416 0 0" xyz="0 0.0 0.078238"/>
      <geometry>
        <mesh filename="package://pa_ctrl/rviz/meshes/collision/Festool_colision.stl"/>
      </geometry>
    </collision>
  </link>
  <link name="robot_base_plate">
    <collision>
      <origin rpy=".0 0.0 0.0" xyz="0.0 0.0 0.0"/>
      <geometry>
        <box size="0.35 0.2 0.01"/>
      </geometry>
    </collision>
  </link>
  <link name="husky">
    <collision>
      <origin rpy="1.5708 0 3.1416" xyz="0 0 0"/>
      <geometry>
        <mesh filename="package://pa_ctrl/rviz/meshes/collision/collision_mesh.stl"/>
      </geometry>
    </collision>
  </link>
  <link name="TCP">
  </link>
  <link name="world"/>
  <link name="camera_frame"/>
  <!-- Diefine joint between link-->
  <joint name="tool0_to_festool_kit" type="fixed">
    <origin rpy="0 0 0" xyz="0 0 0"/>
    <parent link="tool0"/>
    <child link="festool_kit"/>
  </joint>
  <joint name="husky_to_robot_base_plate" type="prismatic">
    <origin rpy="0 0 0" xyz="0.0 0.0 0.798396"/>
    <parent link="husky"/>
    <child link="robot_base_plate"/>
    <axis xyz="0 0 1"/>
    <limit effort="4000.0" lower="0.0" upper="1.050" velocity="0.150"/>
    <!--TODO safety controller/-->
  </joint>
  <joint name="robot_base_plate_to_base_link" type="fixed">
    <origin rpy="0 0 0" xyz="0 0 0"/>
    <parent link="robot_base_plate"/>
    <child link="base_link"/>
  </joint>
  <joint name="festool_kit_to_TCP" type="fixed">
    <origin rpy="0 0 0" xyz="0 -0.020860 0.141701"/>
    <parent link="festool_kit"/>
    <child link="TCP"/>
  </joint>
  <joint name="world_to_husky" type="fixed">
    <origin rpy="0 0 0" xyz="0 0 0"/>
    <parent link="world"/>
    <child link="husky"/>
  </joint>
  <joint name="world_to_camera" type="fixed">
    <parent link="world"/>
    <child link="camera_frame"/>
    <origin rpy="0 3.14159 0" xyz="-0.25 -0.5 1.25"/>
  </joint>
</robot>

